[2024-04-24 06:11:37,737] {taskinstance.py:1179} INFO - Dependencies all met for <TaskInstance: ETL_toll_data.unzip_data manual__2024-04-24T06:06:34.757989+00:00 [queued]>
[2024-04-24 06:11:37,752] {taskinstance.py:1179} INFO - Dependencies all met for <TaskInstance: ETL_toll_data.unzip_data manual__2024-04-24T06:06:34.757989+00:00 [queued]>
[2024-04-24 06:11:37,752] {taskinstance.py:1376} INFO - 
--------------------------------------------------------------------------------
[2024-04-24 06:11:37,752] {taskinstance.py:1377} INFO - Starting attempt 2 of 2
[2024-04-24 06:11:37,752] {taskinstance.py:1378} INFO - 
--------------------------------------------------------------------------------
[2024-04-24 06:11:37,769] {taskinstance.py:1397} INFO - Executing <Task(BashOperator): unzip_data> on 2024-04-24 06:06:34.757989+00:00
[2024-04-24 06:11:37,779] {standard_task_runner.py:52} INFO - Started process 1356 to run task
[2024-04-24 06:11:37,784] {standard_task_runner.py:79} INFO - Running: ['***', 'tasks', 'run', 'ETL_toll_data', 'unzip_data', 'manual__2024-04-24T06:06:34.757989+00:00', '--job-id', '7', '--raw', '--subdir', 'DAGS_FOLDER/finalassignment/staging/ETL_toll_data.py', '--cfg-path', '/tmp/tmp4d47_goq', '--error-file', '/tmp/tmprmicchs8']
[2024-04-24 06:11:37,784] {standard_task_runner.py:80} INFO - Job 7: Subtask unzip_data
[2024-04-24 06:11:37,895] {task_command.py:371} INFO - Running <TaskInstance: ETL_toll_data.unzip_data manual__2024-04-24T06:06:34.757989+00:00 [running]> on host d95240f2060c
[2024-04-24 06:11:38,012] {taskinstance.py:1591} INFO - Exporting the following env vars:
AIRFLOW_CTX_DAG_EMAIL=mayaa@somemail.com
AIRFLOW_CTX_DAG_OWNER=Mayaa p
AIRFLOW_CTX_DAG_ID=ETL_toll_data
AIRFLOW_CTX_TASK_ID=unzip_data
AIRFLOW_CTX_EXECUTION_DATE=2024-04-24T06:06:34.757989+00:00
AIRFLOW_CTX_TRY_NUMBER=2
AIRFLOW_CTX_DAG_RUN_ID=manual__2024-04-24T06:06:34.757989+00:00
[2024-04-24 06:11:38,014] {subprocess.py:62} INFO - Tmp dir root location: 
 /tmp
[2024-04-24 06:11:38,014] {subprocess.py:74} INFO - Running command: ['bash', '-c', 'tar -xzvf /home/project/***/dags/tolldata.tgz -C /home/project/***/dags/finalassignment']
[2024-04-24 06:11:38,036] {subprocess.py:85} INFO - Output:
[2024-04-24 06:11:38,043] {subprocess.py:92} INFO - tar (child): /home/project/***/dags/tolldata.tgz: Cannot open: No such file or directory
[2024-04-24 06:11:38,043] {subprocess.py:92} INFO - tar (child): Error is not recoverable: exiting now
[2024-04-24 06:11:38,043] {subprocess.py:92} INFO - tar: Child returned status 2
[2024-04-24 06:11:38,044] {subprocess.py:92} INFO - tar: Error is not recoverable: exiting now
[2024-04-24 06:11:38,044] {subprocess.py:96} INFO - Command exited with return code 2
[2024-04-24 06:11:38,074] {taskinstance.py:1909} ERROR - Task failed with exception
Traceback (most recent call last):
  File "/home/airflow/.local/lib/python3.7/site-packages/airflow/operators/bash.py", line 195, in execute
    f'Bash command failed. The command returned a non-zero exit code {result.exit_code}.'
airflow.exceptions.AirflowException: Bash command failed. The command returned a non-zero exit code 2.
[2024-04-24 06:11:38,078] {taskinstance.py:1420} INFO - Marking task as FAILED. dag_id=ETL_toll_data, task_id=unzip_data, execution_date=20240424T060634, start_date=20240424T061137, end_date=20240424T061138
[2024-04-24 06:11:38,103] {warnings.py:110} WARNING - /home/***/.local/lib/python3.7/site-packages/***/utils/email.py:119: PendingDeprecationWarning: Fetching SMTP credentials from configuration variables will be deprecated in a future release. Please set credentials using a connection instead.
  send_mime_email(e_from=mail_from, e_to=recipients, mime_msg=msg, conn_id=conn_id, dryrun=dryrun)

[2024-04-24 06:11:38,103] {configuration.py:552} WARNING - section/key [smtp/smtp_user] not found in config
[2024-04-24 06:11:38,103] {email.py:228} INFO - Email alerting: attempt 1
[2024-04-24 06:11:38,117] {configuration.py:552} WARNING - section/key [smtp/smtp_user] not found in config
[2024-04-24 06:11:38,117] {email.py:228} INFO - Email alerting: attempt 1
[2024-04-24 06:11:38,118] {taskinstance.py:1964} ERROR - Failed to send email to: ['mayaa@somemail.com']
Traceback (most recent call last):
  File "/home/airflow/.local/lib/python3.7/site-packages/airflow/models/taskinstance.py", line 1471, in _run_raw_task
    self._execute_task_with_callbacks(context, test_mode)
  File "/home/airflow/.local/lib/python3.7/site-packages/airflow/models/taskinstance.py", line 1618, in _execute_task_with_callbacks
    result = self._execute_task(context, task_orig)
  File "/home/airflow/.local/lib/python3.7/site-packages/airflow/models/taskinstance.py", line 1679, in _execute_task
    result = execute_callable(context=context)
  File "/home/airflow/.local/lib/python3.7/site-packages/airflow/operators/bash.py", line 195, in execute
    f'Bash command failed. The command returned a non-zero exit code {result.exit_code}.'
airflow.exceptions.AirflowException: Bash command failed. The command returned a non-zero exit code 2.

During handling of the above exception, another exception occurred:

Traceback (most recent call last):
  File "/home/airflow/.local/lib/python3.7/site-packages/airflow/models/taskinstance.py", line 2346, in email_alert
    send_email(task.email, subject, html_content)
  File "/home/airflow/.local/lib/python3.7/site-packages/airflow/utils/email.py", line 71, in send_email
    **kwargs,
  File "/home/airflow/.local/lib/python3.7/site-packages/airflow/utils/email.py", line 119, in send_email_smtp
    send_mime_email(e_from=mail_from, e_to=recipients, mime_msg=msg, conn_id=conn_id, dryrun=dryrun)
  File "/home/airflow/.local/lib/python3.7/site-packages/airflow/utils/email.py", line 230, in send_mime_email
    smtp_conn = _get_smtp_connection(smtp_host, smtp_port, smtp_timeout, smtp_ssl)
  File "/home/airflow/.local/lib/python3.7/site-packages/airflow/utils/email.py", line 264, in _get_smtp_connection
    else smtplib.SMTP(host=host, port=port, timeout=timeout)
  File "/usr/local/lib/python3.7/smtplib.py", line 251, in __init__
    (code, msg) = self.connect(host, port)
  File "/usr/local/lib/python3.7/smtplib.py", line 336, in connect
    self.sock = self._get_socket(host, port, self.timeout)
  File "/usr/local/lib/python3.7/smtplib.py", line 307, in _get_socket
    self.source_address)
  File "/usr/local/lib/python3.7/socket.py", line 728, in create_connection
    raise err
  File "/usr/local/lib/python3.7/socket.py", line 716, in create_connection
    sock.connect(sa)
OSError: [Errno 99] Cannot assign requested address

During handling of the above exception, another exception occurred:

Traceback (most recent call last):
  File "/home/airflow/.local/lib/python3.7/site-packages/airflow/models/taskinstance.py", line 1962, in handle_failure
    self.email_alert(error, task)
  File "/home/airflow/.local/lib/python3.7/site-packages/airflow/models/taskinstance.py", line 2348, in email_alert
    send_email(task.email, subject, html_content_err)
  File "/home/airflow/.local/lib/python3.7/site-packages/airflow/utils/email.py", line 71, in send_email
    **kwargs,
  File "/home/airflow/.local/lib/python3.7/site-packages/airflow/utils/email.py", line 119, in send_email_smtp
    send_mime_email(e_from=mail_from, e_to=recipients, mime_msg=msg, conn_id=conn_id, dryrun=dryrun)
  File "/home/airflow/.local/lib/python3.7/site-packages/airflow/utils/email.py", line 230, in send_mime_email
    smtp_conn = _get_smtp_connection(smtp_host, smtp_port, smtp_timeout, smtp_ssl)
  File "/home/airflow/.local/lib/python3.7/site-packages/airflow/utils/email.py", line 264, in _get_smtp_connection
    else smtplib.SMTP(host=host, port=port, timeout=timeout)
  File "/usr/local/lib/python3.7/smtplib.py", line 251, in __init__
    (code, msg) = self.connect(host, port)
  File "/usr/local/lib/python3.7/smtplib.py", line 336, in connect
    self.sock = self._get_socket(host, port, self.timeout)
  File "/usr/local/lib/python3.7/smtplib.py", line 307, in _get_socket
    self.source_address)
  File "/usr/local/lib/python3.7/socket.py", line 728, in create_connection
    raise err
  File "/usr/local/lib/python3.7/socket.py", line 716, in create_connection
    sock.connect(sa)
OSError: [Errno 99] Cannot assign requested address
[2024-04-24 06:11:38,142] {standard_task_runner.py:97} ERROR - Failed to execute job 7 for task unzip_data (Bash command failed. The command returned a non-zero exit code 2.; 1356)
[2024-04-24 06:11:38,155] {local_task_job.py:156} INFO - Task exited with return code 1
[2024-04-24 06:11:38,233] {local_task_job.py:273} INFO - 0 downstream tasks scheduled from follow-on schedule check
